<?xml version="1.0"?>
<sdf version="1.7">

  <!-- Note:
       This file defines the model for a box with two degrees of freedom
       (DOFs): a) one DOF for the horizontal motion along the y axis and
       b) one DOF for the vertical motion along the z axis.
       To this end, this model defines a small "ghost body" between
       the box and the world so that we can attach two prismatic joints for
       these two DOFs. The ghost body has negligible mass.
  -->
  <!-- world->ghost_body_y->ghost_body_z_sphere-->
  <model name="pusher">
    <!-- The model for a solid box of uniform density. -->
    <link name="ghost_body_y"></link>
    <joint name="y_slider" type="prismatic">
      <parent>world</parent>
      <child>ghost_body_y</child>
      <axis>
        <xyz>1 0 0</xyz>
      </axis>
    </joint>

    <joint name="z_slider" type="prismatic">
      <parent>ghost_body_y</parent>
      <child>cylinder</child>
      <axis>
        <xyz>0 1 0</xyz>
      </axis>

    </joint>

    <link name="cylinder">
      <inertial>
        <mass>0.01</mass>

        <inertia>
          <ixx>0.001</ixx>
          <ixy>0</ixy>
          <ixz>0.001</ixz>
          <iyy>1</iyy>
          <iyz>0</iyz>
          <izz>0.001</izz>
        </inertia>
      </inertial>
      <pose>0 0 0.06 0 0 0</pose>

      <visual name="visual">
        <geometry>
          <cylinder>
            <radius> 0.02 </radius>
            <length> 0.1 </length>
          </cylinder>
        </geometry>
        <material>
          <diffuse>0.1 0.5 0.5 0.8</diffuse>
        </material>
      </visual>

      <collision name="collision">
        <geometry>
          <cylinder>
            <radius> 0.02 </radius>
            <length> 0.1 </length>
          </cylinder>        
        </geometry>
        <surface>
          <friction>
            <ode>
              <mu>1.0</mu>
              <mu2>1.0</mu2>
            </ode>
          </friction>
        </surface>
      </collision>
    </link>
  </model>

</sdf>