<?xml version="1.0"?>
<sdf version="1.7">

  <!-- Note:
       This file defines the model for a box with two degrees of freedom
       (DOFs): a) one DOF for the horizontal motion along the y axis and
       b) one DOF for the vertical motion along the z axis.
       To this end, this model defines a small "ghost body" between
       the box and the world so that we can attach two prismatic joints for
       these two DOFs. The ghost body has negligible mass.
  -->
  <model name="pusher">
     <link name="cylinder_x_link">
      <inertial>
        <mass>1.0e-6</mass>
        <inertia>
          <ixx>1.0e-6</ixx>
          <ixy>0</ixy>
          <ixz>0</ixz>
          <iyy>1.0e-6</iyy>
          <iyz>0</iyz>
          <izz>1.0e-6</izz>
        </inertia>
      </inertial>
    </link>

    <link name="pusher">
      <inertial>
        <mass>0.1</mass>
        <inertia>
          <ixx>0.00016895833333333335</ixx>
          <ixy>0</ixy>
          <ixz>0</ixz>
          <iyy>0.00016895833333333335</iyy>
          <iyz>0</iyz>
          <izz>1.125e-05</izz>
        </inertia>
      </inertial>
      <pose>0 0 0.1 0 0 0</pose>

      <visual name="visual">
        <geometry>
          <cylinder>
            <radius> 0.015 </radius>
            <length> 0.14 </length>
          </cylinder>
        </geometry>
        <material>
          <diffuse> 0.80078125 0.1484375 0.1484375 1. </diffuse>
        </material>
      </visual>

      <collision name="collision">
        <geometry>
          <cylinder>
            <radius> 0.015 </radius>
            <length> 0.14 </length>
          </cylinder>        
        </geometry>
        <drake:proximity_properties>
          <drake:compliant_hydroelastic/>
          <drake:hunt_crossley_dissipation>1.25</drake:hunt_crossley_dissipation>
          <drake:hydroelastic_modulus>1e5</drake:hydroelastic_modulus>
          <drake:mesh_resolution_hint>0.005</drake:mesh_resolution_hint>
          <drake:mu_dynamic>0.25</drake:mu_dynamic>
          <drake:mu_static>0.25</drake:mu_static>
        </drake:proximity_properties>
      </collision>
    </link>

    <joint name="x_slider" type="prismatic">
      <parent>world</parent>
      <child>cylinder_x_link</child>
      <axis>
        <xyz>1 0 0</xyz>
        <limit>
          <effort>100</effort>
        </limit>
      </axis>
    </joint>

    <joint name="y_slider" type="prismatic">
      <parent>cylinder_x_link</parent>
      <child>pusher</child>
      <axis>
        <xyz>0 1 0</xyz>
        <limit>
          <effort>100</effort>
        </limit>
      </axis>
    </joint>
  </model>
</sdf>
